Workbook

Sheet Option 1
C2: 0 | D2: 1 | E2: 2 | F2: 3 | G2: 4 | H2: 5 | I2: 6 | J2: 7 | K2: 8 | L2: 9 | M2: 10 | N2: 11 | O2: 12 | P2: 13 | Q2: 14 | R2: 15
C3: 45658 | D3: 2025 | E3: 2026 | F3: 2027 | G3: 2028 | H3: 2029 | I3: 2030 | J3: 2031 | K3: 2032 | L3: 2033 | M3: 2034 | N3: 2035 | O3: 2036 | P3: 2037 | Q3: 2038 | R3: 2039
B5: Volume | C5: 0 | D5: 0 | E5: 0 | F5: 0 | G5: 0 | H5: 0 | I5: 20000 | J5: =I5*(1+$C$33) -> 24000 | K5: =J5*(1+$C$33) -> 28800 | L5: =K5*(1+$C$33) -> 34560 | M5: =L5*(1+$C$33) -> 41472 | N5: =M5*(1+$C$33) -> 49766.4 | O5: =N5*(1+$C$33) -> 59719.68 | P5: =O5*(1+$C$33) -> 71663.616 | Q5: =P5*(1+$C$33) -> 85996.339 | R5: =Q5*(1+$C$33) -> 103195.61
B7: Revenue | C7: 0 | D7: 0 | E7: 0 | F7: 0 | G7: 0 | H7: 0 | I7: =I5*($C$34) -> 2000000000 | J7: =J5*($C$34) -> 2400000000 | K7: =K5*($C$34) -> 2880000000 | L7: =L5*($C$34) -> 3456000000 | M7: =M5*($C$34) -> 4147200000 | N7: =N5*($C$34) -> 4976640000 | O7: =O5*($C$34) -> 5971968000 | P7: =P5*($C$34) -> 7.1663616e+09 | ... R7: =R5*($C$34) -> 1.0319561e+10
B9: Std. Cost | C9: 0 | D9: 0 | E9: 0 | F9: 0 | G9: 0 | H9: 0 | I9: =I5*(I35) -> 1600000000 | J9: =J5*(J35) -> 1920000000 | K9: =K5*(K35) -> 2304000000 | L9: =L5*(L35) -> 2764800000 | M9: =M5*(M35) -> 3234816000 | N9: =N5*(N35) -> 3881779200 | O9: =O5*(O35) -> 4538695680 | P9: =P5*(P35) -> 5446434816 | ... R9: =R5*(R35) -> 7.6364749e+09
B10: Warranty | C10: 0 | D10: 0 | E10: 0 | F10: 0 | G10: 0 | H10: 0 | I10: =I5*($C$36) -> 20000000 | J10: =J5*($C$36) -> 24000000 | K10: =K5*($C$36) -> 28800000 | L10: =L5*($C$36) -> 34560000 | M10: =M5*($C$36) -> 41472000 | N10: =N5*($C$36) -> 49766400 | O10: =O5*($C$36) -> 59719680 | P10: =P5*($C$36) -> 71663616 | ... R10: =R5*($C$36) -> 1.0319561e+08
B11: Total COGS | C11: 0 | D11: 0 | E11: 0 | F11: 0 | G11: 0 | H11: 0 | I11: =I9+I10 -> 1620000000 | J11: =J9+J10 -> 1944000000 | K11: =K9+K10 -> 2332800000 | L11: =L9+L10 -> 2799360000 | M11: =M9+M10 -> 3276288000 | N11: =N9+N10 -> 3931545600 | O11: =O9+O10 -> 4598415360 | P11: =P9+P10 -> 5518098432 | ... R11: =R9+R10 -> 7.7396705e+09
B13: Gross Margin $ | C13: 0 | D13: 0 | E13: 0 | F13: 0 | G13: 0 | H13: 0 | I13: =I7-I11 -> 380000000 | J13: =J7-J11 -> 456000000 | K13: =K7-K11 -> 547200000 | L13: =L7-L11 -> 656640000 | M13: =M7-M11 -> 870912000 | N13: =N7-N11 -> 1045094400 | O13: =O7-O11 -> 1373552640 | P13: =P7-P11 -> 1.6482632e+09 | ... R13: =R7-R11 -> 2.5798902e+09
B15: Selling and Admin O/H | C15: 0 | D15: 160000000 | E15: =D15*(1+$C$38) -> 168000000 | F15: =E15*(1+$C$38) -> 176400000 | G15: =F15*(1+$C$38) -> 185220000 | H15: =G15*(1+$C$38) -> 194481000 | I15: =H15*(1+$C$38) -> 204205050 | J15: =I15*(1+$C$38) -> 2.144153e+08 | K15: =J15*(1+$C$38) -> 2.2513607e+08 | L15: =K15*(1+$C$38) -> 2.3639287e+08 | ... R15: =Q15*(1+$C$38) -> 3.1678906e+08
B16: Development Expense | C16: 0 | D16: 120000000 | E16: 120000000 | F16: 120000000 | G16: 120000000 | H16: 120000000 | I16: 120000000 | J16: 120000000 | K16: 120000000 | L16: 120000000 | M16: 120000000 | N16: 120000000 | O16: 120000000 | P16: 120000000 | Q16: 120000000 | R16: 120000000
B18: EBITDA | C18: 0 | D18: =D13-D15-D16 -> -280000000 | E18: =E13-E15-E16 -> -288000000 | F18: =F13-F15-F16 -> -296400000 | G18: =G13-G15-G16 -> -305220000 | H18: =H13-H15-H16 -> -314481000 | I18: =I13-I15-I16 -> 55794950 | J18: =J13-J15-J16 -> 1.215847e+08 | K18: =K13-K15-K16 -> 2.0206393e+08 | ... R18: =R13-R15-R16 -> 2.1431011e+09
B19: Depreciation | C19: 0 | D19: 5000000 | E19: 5000000 | F19: 5000000 | G19: 5000000 | H19: 5000000 | I19: 5000000 | J19: 5000000 | K19: 5000000 | L19: 5000000 | M19: 5000000 | N19: 5000000 | O19: 5000000 | P19: 5000000 | Q19: 5000000 | R19: 5000000
B20: Income Tax Expense | C20: 0 | D20: =MAX(0,(D18-D19)*$C$43) -> 0 | E20: =MAX(0,(E18-E19)*$C$43) -> 0 | F20: =MAX(0,(F18-F19)*$C$43) -> 0 | G20: =MAX(0,(G18-G19)*$C$43) -> 0 | H20: =MAX(0,(H18-H19)*$C$43) -> 0 | I20: =MAX(0,(I18-I19)*$C$43) -> 12698738 | J20: =MAX(0,(J18-J19)*$C$43) -> 29146174 | K20: =MAX(0,(K18-K19)*$C$43) -> 49265983 | ... R20: =MAX(0,(R18-R19)*$C$43) -> 5.3452528e+08
B22: Net Working Capital | C22: 0 | D22: 0 | E22: 0 | F22: 0 | G22: 0 | H22: 0 | I22: =I7*($C$41) -> 100000000 | J22: =J7*($C$41) -> 120000000 | K22: =K7*($C$41) -> 144000000 | L22: =L7*($C$41) -> 172800000 | M22: =M7*($C$41) -> 207360000 | N22: =N7*($C$41) -> 248832000 | O22: =O7*($C$41) -> 298598400 | P22: =P7*($C$41) -> 358318080 | ... R22: =R7*($C$41) -> 5.1597804e+08
B23: Net Change in WC | C23: 0 | D23: 0 | E23: 0 | F23: 0 | G23: 0 | H23: 0 | I23: =I22-H22 -> 100000000 | J23: =J22-I22 -> 20000000 | K23: =K22-J22 -> 24000000 | L23: =L22-K22 -> 28800000 | M23: =M22-L22 -> 34560000 | N23: =N22-M22 -> 41472000 | O23: =O22-N22 -> 49766400 | P23: =P22-O22 -> 59719680 | ... R23: =R22-Q22 -> 85996339
B24: Capital Expenditure | C24: 0 | D24: 20000000 | E24: 20000000 | F24: 20000000 | G24: 20000000 | H24: 20000000 | I24: 0 | J24: 0 | K24: 0 | L24: 0 | M24: 0 | N24: 0 | O24: 0 | P24: 0 | Q24: 0 | R24: 0
B26: Free Cash Flow | C26: 0 | D26: =D18+D19-D20-D23-D24 -> -295000000 | E26: =E18+E19-E20-E23-E24 -> -303000000 | F26: =F18+F19-F20-F23-F24 -> -311400000 | G26: =G18+G19-G20-G23-G24 -> -320220000 | H26: =H18+H19-H20-H23-H24 -> -329481000 | I26: =I18+I19-I20-I23-I24 -> -51903788 | J26: =J18+J19-J20-J23-J24 -> 77438523 | K26: =K18+K19-K20-K23-K24 -> 1.3379795e+08 | ... R26: =R18+R19-R20-R23-R24 -> 1.5275795e+09
B27: Cumulative Free Cashflow | C27: 0 | D27: =C27+D26 -> -295000000 | E27: =D27+E26 -> -598000000 | F27: =E27+F26 -> -909400000 | G27: =F27+G26 -> -1229620000 | H27: =G27+H26 -> -1559101000 | I27: =H27+I26 -> -1.6110048e+09 | J27: =I27+J26 -> -1.5335663e+09 | K27: =J27+K26 -> -1.3997683e+09 | ... R27: =Q27+R26 -> 3.8771675e+09
B29: Option 1: Keep X15 Engine
B30: Base case / bare minimum to comply with laws
B31: Value Drivers
B32: Volume in 2030 | C32: 20000 | D32: units
B33: Volume Growth rate | C33: 0.2
B34: Price per unit | C34: 100000 | I34: 2030 | J34: 2031 | K34: 2032 | L34: 2033 | M34: 2034 | N34: 2035 | O34: 2036 | P34: 2037 | Q34: 2038 | R34: 2039
B35: Cost per unit (timeline to the right) | I35: 80000 | J35: 80000 | K35: 80000 | L35: 80000 | M35: 78000 | N35: 78000 | O35: 76000 | P35: 76000 | Q35: 75000 | R35: 74000
B36: Warranty cost per unit | C36: 1000
B37: Selling and Admin in 2025 | C37: 160000000
B38: Selling and Admin growth rate | C38: 0.05
B39: Depreciation | C39: 5000000 | D39: per year
B40: Development Expense | C40: 120000000 | D40: per year
B41: Net working capital | C41: 0.05 | D41: of sales
B42: Capital Expenditure | C42: 20000000 | D42: per year
B43: Tax Rate | C43: 0.25
B44: Interest/Discount rate | C44: 0.15
B46: Net Present Value | C46: =NPV($C$44,D26:R26)+C26 -> -1.1916693e+08

Sheet Sensitve Analysis #1 Option 1
C2: 0 | D2: 1 | E2: 2 | F2: 3 | G2: 4 | H2: 5 | I2: 6 | J2: 7 | K2: 8 | L2: 9 | M2: 10 | N2: 11 | O2: 12 | P2: 13 | Q2: 14 | R2: 15
C3: 45658 | D3: 2025 | E3: 2026 | F3: 2027 | G3: 2028 | H3: 2029 | I3: 2030 | J3: 2031 | K3: 2032 | L3: 2033 | M3: 2034 | N3: 2035 | O3: 2036 | P3: 2037 | Q3: 2038 | R3: 2039
B5: Volume | C5: 0 | D5: 0 | E5: 0 | F5: 0 | G5: 0 | H5: 0 | I5: =C33 -> 15000 | J5: =I5*(1+$C$34) -> 18000 | K5: =J5*(1+$C$34) -> 21600 | L5: =K5*(1+$C$34) -> 25920 | M5: =L5*(1+$C$34) -> 31104 | N5: =M5*(1+$C$34) -> 37324.8 | O5: =N5*(1+$C$34) -> 44789.76 | P5: =O5*(1+$C$34) -> 53747.712 | Q5: =P5*(1+$C$34) -> 64497.254 | R5: =Q5*(1+$C$34) -> 77396.705
B7: Revenue | C7: 0 | D7: 0 | E7: 0 | F7: 0 | G7: 0 | H7: 0 | I7: =I5*($C$35) -> 1500000000 | J7: =J5*($C$35) -> 1800000000 | K7: =K5*($C$35) -> 2160000000 | L7: =L5*($C$35) -> 2592000000 | M7: =M5*($C$35) -> 3110400000 | N7: =N5*($C$35) -> 3.73248e+09 | O7: =O5*($C$35) -> 4.478976e+09 | P7: =P5*($C$35) -> 5.3747712e+09 | ... R7: =R5*($C$35) -> 7.7396705e+09
B9: Std. Cost | C9: 0 | D9: 0 | E9: 0 | F9: 0 | G9: 0 | H9: 0 | I9: =I5*(I36) -> 1200000000 | J9: =J5*(J36) -> 1440000000 | K9: =K5*(K36) -> 1728000000 | L9: =L5*(L36) -> 2073600000 | M9: =M5*(M36) -> 2426112000 | N9: =N5*(N36) -> 2.9113344e+09 | O9: =O5*(O36) -> 3.4040218e+09 | P9: =P5*(P36) -> 4.0848261e+09 | ... R9: =R5*(R36) -> 5.7273562e+09
B10: Warranty | C10: 0 | D10: 0 | E10: 0 | F10: 0 | G10: 0 | H10: 0 | I10: =I5*($C$37) -> 15000000 | J10: =J5*($C$37) -> 18000000 | K10: =K5*($C$37) -> 21600000 | L10: =L5*($C$37) -> 25920000 | M10: =M5*($C$37) -> 31104000 | N10: =N5*($C$37) -> 37324800 | O10: =O5*($C$37) -> 44789760 | P10: =P5*($C$37) -> 53747712 | ... R10: =R5*($C$37) -> 77396705
B11: Total COGS | C11: 0 | D11: 0 | E11: 0 | F11: 0 | G11: 0 | H11: 0 | I11: =I9+I10 -> 1215000000 | J11: =J9+J10 -> 1458000000 | K11: =K9+K10 -> 1749600000 | L11: =L9+L10 -> 2099520000 | M11: =M9+M10 -> 2457216000 | N11: =N9+N10 -> 2.9486592e+09 | O11: =O9+O10 -> 3.4488115e+09 | P11: =P9+P10 -> 4.1385738e+09 | ... R11: =R9+R10 -> 5.8047529e+09
B13: Gross Margin $ | C13: 0 | D13: 0 | E13: 0 | F13: 0 | G13: 0 | H13: 0 | I13: =I7-I11 -> 285000000 | J13: =J7-J11 -> 342000000 | K13: =K7-K11 -> 410400000 | L13: =L7-L11 -> 492480000 | M13: =M7-M11 -> 653184000 | N13: =N7-N11 -> 783820800 | O13: =O7-O11 -> 1.0301645e+09 | P13: =P7-P11 -> 1.2361974e+09 | ... R13: =R7-R11 -> 1934917632
B15: Selling and Admin O/H | C15: 0 | D15: 160000000 | E15: =D15*(1+$C$39) -> 168000000 | F15: =E15*(1+$C$39) -> 176400000 | G15: =F15*(1+$C$39) -> 185220000 | H15: =G15*(1+$C$39) -> 194481000 | I15: =H15*(1+$C$39) -> 204205050 | J15: =I15*(1+$C$39) -> 2.144153e+08 | K15: =J15*(1+$C$39) -> 2.2513607e+08 | L15: =K15*(1+$C$39) -> 2.3639287e+08 | ... R15: =Q15*(1+$C$39) -> 3.1678906e+08
B16: Development Expense | C16: 0 | D16: 120000000 | E16: 120000000 | F16: 120000000 | G16: 120000000 | H16: 120000000 | I16: 120000000 | J16: 120000000 | K16: 120000000 | L16: 120000000 | M16: 120000000 | N16: 120000000 | O16: 120000000 | P16: 120000000 | Q16: 120000000 | R16: 120000000
B18: EBITDA | C18: =C13-C15-C16 -> 0 | D18: =D13-D15-D16 -> -280000000 | E18: =E13-E15-E16 -> -288000000 | F18: =F13-F15-F16 -> -296400000 | G18: =G13-G15-G16 -> -305220000 | H18: =H13-H15-H16 -> -314481000 | I18: =I13-I15-I16 -> -39205050 | J18: =J13-J15-J16 -> 7584697.5 | ... R18: =R13-R15-R16 -> 1.4981286e+09
B19: Depreciation | C19: 0 | D19: 5000000 | E19: 5000000 | F19: 5000000 | G19: 5000000 | H19: 5000000 | I19: 5000000 | J19: 5000000 | K19: 5000000 | L19: 5000000 | M19: 5000000 | N19: 5000000 | O19: 5000000 | P19: 5000000 | Q19: 5000000 | R19: 5000000
B20: Income Tax Expense | C20: 0 | D20: =MAX(0,(D18-D19)*$C$44) -> 0 | E20: =MAX(0,(E18-E19)*$C$44) -> 0 | F20: =MAX(0,(F18-F19)*$C$44) -> 0 | G20: =MAX(0,(G18-G19)*$C$44) -> 0 | H20: =MAX(0,(H18-H19)*$C$44) -> 0 | I20: =MAX(0,(I18-I19)*$C$44) -> 0 | J20: =MAX(0,(J18-J19)*$C$44) -> 646174.38 | K20: =MAX(0,(K18-K19)*$C$44) -> 15065983 | ... R20: =MAX(0,(R18-R19)*$C$44) -> 3.7328214e+08
B22: Net Working Capital | C22: 0 | D22: 0 | E22: 0 | F22: 0 | G22: 0 | H22: 0 | I22: =I7*($C$42) -> 75000000 | J22: =J7*($C$42) -> 90000000 | K22: =K7*($C$42) -> 108000000 | L22: =L7*($C$42) -> 129600000 | M22: =M7*($C$42) -> 155520000 | N22: =N7*($C$42) -> 186624000 | O22: =O7*($C$42) -> 2.239488e+08 | P22: =P7*($C$42) -> 2.6873856e+08 | ... R22: =R7*($C$42) -> 3.8698353e+08
B23: Net Change in WC | C23: 0 | D23: 0 | E23: 0 | F23: 0 | G23: 0 | H23: 0 | I23: =I22-H22 -> 75000000 | J23: =J22-I22 -> 15000000 | K23: =K22-J22 -> 18000000 | L23: =L22-K22 -> 21600000 | M23: =M22-L22 -> 25920000 | N23: =N22-M22 -> 31104000 | O23: =O22-N22 -> 37324800 | P23: =P22-O22 -> 44789760 | ... R23: =R22-Q22 -> 64497254
B24: Capital Expenditure | C24: 0 | D24: 20000000 | E24: 20000000 | F24: 20000000 | G24: 20000000 | H24: 20000000 | I24: 0 | J24: 0 | K24: 0 | L24: 0 | M24: 0 | N24: 0 | O24: 0 | P24: 0 | Q24: 0 | R24: 0
B26: Free Cash Flow | C26: 0 | D26: =D18+D19-D20-D23-D24 -> -295000000 | E26: =E18+E19-E20-E23-E24 -> -303000000 | F26: =F18+F19-F20-F23-F24 -> -311400000 | G26: =G18+G19-G20-G23-G24 -> -320220000 | H26: =H18+H19-H20-H23-H24 -> -329481000 | I26: =I18+I19-I20-I23-I24 -> -109205050 | J26: =J18+J19-J20-J23-J24 -> -3061476.9 | K26: =K18+K19-K20-K23-K24 -> 37197949 | ... R26: =R18+R19-R20-R23-R24 -> 1.0653492e+09
B27: Cumulative Free Cashflow | C27: 0 | D27: =C27+D26 -> -295000000 | E27: =D27+E26 -> -598000000 | F27: =E27+F26 -> -909400000 | G27: =F27+G26 -> -1229620000 | H27: =G27+H26 -> -1559101000 | I27: =H27+I26 -> -1668306050 | J27: =I27+J26 -> -1.6713675e+09 | K27: =J27+K26 -> -1.6341696e+09 | ... R27: =Q27+R26 -> 1.8160861e+09
B29: Sensitve Analysis #1: Volume for option 1 decreased by 25%
B30: Option 1: Keep X15 Engine
B31: Base case / bare minimum to comply with laws
B32: Value Drivers
B33: Volume in 2030 | C33: =20000*75% -> 15000 | D33: units
B34: Volume Growth rate | C34: 0.2
B35: Price per unit | C35: 100000 | I35: 2030 | J35: 2031 | K35: 2032 | L35: 2033 | M35: 2034 | N35: 2035 | O35: 2036 | P35: 2037 | Q35: 2038 | R35: 2039
B36: Cost per unit (timeline to the right) | I36: 80000 | J36: 80000 | K36: 80000 | L36: 80000 | M36: 78000 | N36: 78000 | O36: 76000 | P36: 76000 | Q36: 75000 | R36: 74000
B37: Warranty cost per unit | C37: 1000
B38: Selling and Admin in 2025 | C38: 160000000
B39: Selling and Admin growth rate | C39: 0.05
B40: Depreciation | C40: 5000000 | D40: per year
B41: Development Expense | C41: 120000000 | D41: per year
B42: Net working capital | C42: 0.05 | D42: of sales
B43: Capital Expenditure | C43: 20000000 | D43: per year
B44: Tax Rate | C44: 0.25
B45: Interest/Discount rate | C45: 0.15
B47: Net Present Value | C47: =NPV($C$45,D26:R26)+C26 -> -5.1943137e+08

Sheet Sensitve Analysis #2 option 1
C2: 0 | D2: 1 | E2: 2 | F2: 3 | G2: 4 | H2: 5 | I2: 6 | J2: 7 | K2: 8 | L2: 9 | M2: 10 | N2: 11 | O2: 12 | P2: 13 | Q2: 14 | R2: 15
C3: 45658 | D3: 2025 | E3: 2026 | F3: 2027 | G3: 2028 | H3: 2029 | I3: 2030 | J3: 2031 | K3: 2032 | L3: 2033 | M3: 2034 | N3: 2035 | O3: 2036 | P3: 2037 | Q3: 2038 | R3: 2039
B5: Volume | C5: 0 | D5: 0 | E5: 0 | F5: 0 | G5: 0 | H5: 0 | I5: =C33 -> 20000 | J5: =I5*(1+$C$34) -> 24000 | K5: =J5*(1+$C$34) -> 28800 | L5: =K5*(1+$C$34) -> 34560 | M5: =L5*(1+$C$34) -> 41472 | N5: =M5*(1+$C$34) -> 49766.4 | O5: =N5*(1+$C$34) -> 59719.68 | P5: =O5*(1+$C$34) -> 71663.616 | Q5: =P5*(1+$C$34) -> 85996.339 | R5: =Q5*(1+$C$34) -> 103195.61
B7: Revenue | C7: 0 | D7: 0 | E7: 0 | F7: 0 | G7: 0 | H7: 0 | I7: =I5*($C$35) -> 2000000000 | J7: =J5*($C$35) -> 2400000000 | K7: =K5*($C$35) -> 2880000000 | L7: =L5*($C$35) -> 3456000000 | M7: =M5*($C$35) -> 4147200000 | N7: =N5*($C$35) -> 4976640000 | O7: =O5*($C$35) -> 5971968000 | P7: =P5*($C$35) -> 7.1663616e+09 | ... R7: =R5*($C$35) -> 1.0319561e+10
B9: Std. Cost | C9: 0 | D9: 0 | E9: 0 | F9: 0 | G9: 0 | H9: 0 | I9: =I5*(I36) -> 1616000000 | J9: =J5*(J36) -> 1939200000 | K9: =K5*(K36) -> 2327040000 | L9: =L5*(L36) -> 2792448000 | M9: =M5*(M36) -> 3267164160 | N9: =N5*(N36) -> 3920596992 | O9: =O5*(O36) -> 4.5840826e+09 | P9: =P5*(P36) -> 5.5008992e+09 | ... R9: =R5*(R36) -> 7.7128397e+09
B10: Warranty | C10: 0 | D10: 0 | E10: 0 | F10: 0 | G10: 0 | H10: 0 | I10: =I5*($C$37) -> 20000000 | J10: =J5*($C$37) -> 24000000 | K10: =K5*($C$37) -> 28800000 | L10: =L5*($C$37) -> 34560000 | M10: =M5*($C$37) -> 41472000 | N10: =N5*($C$37) -> 49766400 | O10: =O5*($C$37) -> 59719680 | P10: =P5*($C$37) -> 71663616 | ... R10: =R5*($C$37) -> 1.0319561e+08
B11: Total COGS | C11: 0 | D11: 0 | E11: 0 | F11: 0 | G11: 0 | H11: 0 | I11: =I9+I10 -> 1636000000 | J11: =J9+J10 -> 1963200000 | K11: =K9+K10 -> 2355840000 | L11: =L9+L10 -> 2827008000 | M11: =M9+M10 -> 3308636160 | N11: =N9+N10 -> 3970363392 | O11: =O9+O10 -> 4.6438023e+09 | P11: =P9+P10 -> 5.5725628e+09 | ... R11: =R9+R10 -> 7.8160353e+09
B13: Gross Margin $ | C13: 0 | D13: 0 | E13: 0 | F13: 0 | G13: 0 | H13: 0 | I13: =I7-I11 -> 364000000 | J13: =J7-J11 -> 436800000 | K13: =K7-K11 -> 524160000 | L13: =L7-L11 -> 628992000 | M13: =M7-M11 -> 838563840 | N13: =N7-N11 -> 1006276608 | O13: =O7-O11 -> 1.3281657e+09 | P13: =P7-P11 -> 1.5937988e+09 | ... R13: =R7-R11 -> 2.5035254e+09
B15: Selling and Admin O/H | C15: 0 | D15: 160000000 | E15: =D15*(1+$C$39) -> 168000000 | F15: =E15*(1+$C$39) -> 176400000 | G15: =F15*(1+$C$39) -> 185220000 | H15: =G15*(1+$C$39) -> 194481000 | I15: =H15*(1+$C$39) -> 204205050 | J15: =I15*(1+$C$39) -> 2.144153e+08 | K15: =J15*(1+$C$39) -> 2.2513607e+08 | L15: =K15*(1+$C$39) -> 2.3639287e+08 | ... R15: =Q15*(1+$C$39) -> 3.1678906e+08
B16: Development Expense | C16: 0 | D16: 120000000 | E16: 120000000 | F16: 120000000 | G16: 120000000 | H16: 120000000 | I16: 120000000 | J16: 120000000 | K16: 120000000 | L16: 120000000 | M16: 120000000 | N16: 120000000 | O16: 120000000 | P16: 120000000 | Q16: 120000000 | R16: 120000000
B18: EBITDA | C18: =C13-C15-C16 -> 0 | D18: =D13-D15-D16 -> -280000000 | E18: =E13-E15-E16 -> -288000000 | F18: =F13-F15-F16 -> -296400000 | G18: =G13-G15-G16 -> -305220000 | H18: =H13-H15-H16 -> -314481000 | I18: =I13-I15-I16 -> 39794950 | J18: =J13-J15-J16 -> 1.023847e+08 | ... R18: =R13-R15-R16 -> 2.0667364e+09
B19: Depreciation | C19: 0 | D19: 5000000 | E19: 5000000 | F19: 5000000 | G19: 5000000 | H19: 5000000 | I19: 5000000 | J19: 5000000 | K19: 5000000 | L19: 5000000 | M19: 5000000 | N19: 5000000 | O19: 5000000 | P19: 5000000 | Q19: 5000000 | R19: 5000000
B20: Income Tax Expense | C20: 0 | D20: =MAX(0,(D18-D19)*$C$44) -> 0 | E20: =MAX(0,(E18-E19)*$C$44) -> 0 | F20: =MAX(0,(F18-F19)*$C$44) -> 0 | G20: =MAX(0,(G18-G19)*$C$44) -> 0 | H20: =MAX(0,(H18-H19)*$C$44) -> 0 | I20: =MAX(0,(I18-I19)*$C$44) -> 8698737.5 | J20: =MAX(0,(J18-J19)*$C$44) -> 24346174 | K20: =MAX(0,(K18-K19)*$C$44) -> 43505983 | ... R20: =MAX(0,(R18-R19)*$C$44) -> 5.1543409e+08
B22: Net Working Capital | C22: 0 | D22: 0 | E22: 0 | F22: 0 | G22: 0 | H22: 0 | I22: =I7*($C$42) -> 100000000 | J22: =J7*($C$42) -> 120000000 | K22: =K7*($C$42) -> 144000000 | L22: =L7*($C$42) -> 172800000 | M22: =M7*($C$42) -> 207360000 | N22: =N7*($C$42) -> 248832000 | O22: =O7*($C$42) -> 298598400 | P22: =P7*($C$42) -> 358318080 | ... R22: =R7*($C$42) -> 5.1597804e+08
B23: Net Change in WC | C23: 0 | D23: 0 | E23: 0 | F23: 0 | G23: 0 | H23: 0 | I23: =I22-H22 -> 100000000 | J23: =J22-I22 -> 20000000 | K23: =K22-J22 -> 24000000 | L23: =L22-K22 -> 28800000 | M23: =M22-L22 -> 34560000 | N23: =N22-M22 -> 41472000 | O23: =O22-N22 -> 49766400 | P23: =P22-O22 -> 59719680 | ... R23: =R22-Q22 -> 85996339
B24: Capital Expenditure | C24: 0 | D24: 20000000 | E24: 20000000 | F24: 20000000 | G24: 20000000 | H24: 20000000 | I24: 0 | J24: 0 | K24: 0 | L24: 0 | M24: 0 | N24: 0 | O24: 0 | P24: 0 | Q24: 0 | R24: 0
B26: Free Cash Flow | C26: 0 | D26: =D18+D19-D20-D23-D24 -> -295000000 | E26: =E18+E19-E20-E23-E24 -> -303000000 | F26: =F18+F19-F20-F23-F24 -> -311400000 | G26: =G18+G19-G20-G23-G24 -> -320220000 | H26: =H18+H19-H20-H23-H24 -> -329481000 | I26: =I18+I19-I20-I23-I24 -> -63903788 | J26: =J18+J19-J20-J23-J24 -> 63038523 | K26: =K18+K19-K20-K23-K24 -> 1.1651795e+08 | ... R26: =R18+R19-R20-R23-R24 -> 1.4703059e+09
B27: Cumulative Free Cashflow | C27: 0 | D27: =C27+D26 -> -295000000 | E27: =D27+E26 -> -598000000 | F27: =E27+F26 -> -909400000 | G27: =F27+G26 -> -1229620000 | H27: =G27+H26 -> -1559101000 | I27: =H27+I26 -> -1.6230048e+09 | J27: =I27+J26 -> -1.5599663e+09 | K27: =J27+K26 -> -1.4434483e+09 | ... R27: =Q27+R26 -> 3.578842e+09
B29: Sensitve Analysis #2: cost/unit increase by 1%
B30: Option 1: Keep X15 Engine
B31: Base case / bare minimum to comply with laws
B32: Value Drivers
B33: Volume in 2030 | C33: 20000 | D33: units
B34: Volume Growth rate | C34: 0.2
B35: Price per unit | C35: 100000 | I35: 2030 | J35: 2031 | K35: 2032 | L35: 2033 | M35: 2034 | N35: 2035 | O35: 2036 | P35: 2037 | Q35: 2038 | R35: 2039
B36: Cost per unit (timeline to the right) | I36: ='Option 1'!I35*1.01 -> 80800 | J36: ='Option 1'!J35*1.01 -> 80800 | K36: ='Option 1'!K35*1.01 -> 80800 | L36: ='Option 1'!L35*1.01 -> 80800 | M36: ='Option 1'!M35*1.01 -> 78780 | N36: ='Option 1'!N35*1.01 -> 78780 | O36: ='Option 1'!O35*1.01 -> 76760 | P36: ='Option 1'!P35*1.01 -> 76760 | ... R36: ='Option 1'!R35*1.01 -> 74740
B37: Warranty cost per unit | C37: =1000 -> 1000
B38: Selling and Admin in 2025 | C38: 160000000
B39: Selling and Admin growth rate | C39: 0.05
B40: Depreciation | C40: 5000000 | D40: per year
B41: Development Expense | C41: 120000000 | D41: per year
B42: Net working capital | C42: 0.05 | D42: of sales
B43: Capital Expenditure | C43: 20000000 | D43: per year
B44: Tax Rate | C44: 0.25
B45: Interest/Discount rate | C45: 0.15
B47: Net Present Value | C47: =NPV($C$45,D26:R26)+C26 -> -1.8044281e+08

Sheet Option 2
C2: 0 | D2: 1 | E2: 2 | F2: 3 | G2: 4 | H2: 5 | I2: 6 | J2: 7 | K2: 8 | L2: 9 | M2: 10 | N2: 11 | O2: 12 | P2: 13 | Q2: 14 | R2: 15
C3: 45658 | D3: 2025 | E3: 2026 | F3: 2027 | G3: 2028 | H3: 2029 | I3: 2030 | J3: 2031 | K3: 2032 | L3: 2033 | M3: 2034 | N3: 2035 | O3: 2036 | P3: 2037 | Q3: 2038 | R3: 2039
B5: Volume | C5: 0 | D5: 0 | E5: 0 | F5: 0 | G5: 0 | H5: 0 | I5: 20000 | J5: =I5*(1+$C$33) -> 26000 | K5: =J5*(1+$C$33) -> 33800 | L5: =K5*(1+$C$33) -> 43940 | M5: =L5*(1+$C$33) -> 57122 | N5: =M5*(1+$C$33) -> 74258.6 | O5: =N5*(1+$C$33) -> 96536.18 | P5: =O5*(1+$C$33) -> 125497.03 | Q5: =P5*(1+$C$33) -> 163146.14 | R5: =Q5*(1+$C$33) -> 212089.99
B7: Revenue | C7: $ - | D7: 0 | E7: 0 | F7: 0 | G7: 0 | H7: 0 | I7: =I5*($C$34) -> 2000000000 | J7: =J5*($C$34) -> 2600000000 | K7: =K5*($C$34) -> 3380000000 | L7: =L5*($C$34) -> 4394000000 | M7: =M5*($C$34) -> 5712200000 | N7: =N5*($C$34) -> 7.42586e+09 | O7: =O5*($C$34) -> 9653618000 | P7: =P5*($C$34) -> 1.2549703e+10 | ... R7: =R5*($C$34) -> 2.1208999e+10
B9: Std. Cost | C9: $ - | D9: 0 | E9: 0 | F9: 0 | G9: 0 | H9: 0 | I9: =I5*(I35) -> 1600000000 | J9: =J5*(J35) -> 2080000000 | K9: =K5*(K35) -> 2704000000 | L9: =L5*(L35) -> 3515200000 | M9: =M5*(M35) -> 4455516000 | N9: =N5*(N35) -> 5792170800 | O9: =O5*(O35) -> 7.3367497e+09 | P9: =P5*(P35) -> 9.5377746e+09 | ... R9: =R5*(R35) -> 1.5694659e+10
B10: Warranty | C10: $ - | D10: 0 | E10: 0 | F10: 0 | G10: 0 | H10: 0 | I10: =I5*($C$36) -> 20000000 | J10: =J5*($C$36) -> 26000000 | K10: =K5*($C$36) -> 33800000 | L10: =L5*($C$36) -> 43940000 | M10: =M5*($C$36) -> 57122000 | N10: =N5*($C$36) -> 74258600 | O10: =O5*($C$36) -> 96536180 | P10: =P5*($C$36) -> 1.2549703e+08 | ... R10: =R5*($C$36) -> 2.1208999e+08
B11: Total COGS | C11: $ - | D11: 0 | E11: 0 | F11: 0 | G11: 0 | H11: 0 | I11: =I9+I10 -> 1620000000 | J11: =J9+J10 -> 2106000000 | K11: =K9+K10 -> 2737800000 | L11: =L9+L10 -> 3559140000 | M11: =M9+M10 -> 4512638000 | N11: =N9+N10 -> 5866429400 | O11: =O9+O10 -> 7.4332859e+09 | P11: =P9+P10 -> 9.6632716e+09 | ... R11: =R9+R10 -> 1.5906749e+10
B13: Gross Margin $ | C13: $ - | D13: 0 | E13: 0 | F13: 0 | G13: 0 | H13: 0 | I13: =I7-I11 -> 380000000 | J13: =J7-J11 -> 494000000 | K13: =K7-K11 -> 642200000 | L13: =L7-L11 -> 834860000 | M13: =M7-M11 -> 1199562000 | N13: =N7-N11 -> 1.5594306e+09 | O13: =O7-O11 -> 2.2203321e+09 | P13: =P7-P11 -> 2886431782 | ... R13: =R7-R11 -> 5.3022497e+09
B15: Selling and Admin O/H | C15: $ - | D15: 160000000 | E15: =D15*(1+$C$38) -> 168000000 | F15: =E15*(1+$C$38) -> 176400000 | G15: =F15*(1+$C$38) -> 185220000 | H15: =G15*(1+$C$38) -> 194481000 | I15: =H15*(1+$C$38) -> 204205050 | J15: =I15*(1+$C$38) -> 2.144153e+08 | K15: =J15*(1+$C$38) -> 2.2513607e+08 | L15: =K15*(1+$C$38) -> 2.3639287e+08 | ... R15: =Q15*(1+$C$38) -> 3.1678906e+08
B16: Development Expense | C16: $ - | D16: =$C$40 -> 150000000 | E16: =$C$40 -> 150000000 | F16: =$C$40 -> 150000000 | G16: =$C$40 -> 150000000 | H16: =$C$40 -> 150000000 | I16: =$C$40 -> 150000000 | J16: =$C$40 -> 150000000 | K16: =$C$40 -> 150000000 | ... R16: =$C$40 -> 150000000
B18: EBITDA | C18: $ - | D18: =D13-D15-D16 -> -310000000 | E18: =E13-E15-E16 -> -318000000 | F18: =F13-F15-F16 -> -326400000 | G18: =G13-G15-G16 -> -335220000 | H18: =H13-H15-H16 -> -344481000 | I18: =I13-I15-I16 -> 25794950 | J18: =J13-J15-J16 -> 1.295847e+08 | K18: =K13-K15-K16 -> 2.6706393e+08 | ... R18: =R13-R15-R16 -> 4.8354606e+09
B19: Depreciation | C19: $ - | D19: 5000000 | E19: 5000000 | F19: 5000000 | G19: 5000000 | H19: 5000000 | I19: 5000000 | J19: 5000000 | K19: 5000000 | L19: 5000000 | M19: 5000000 | N19: 5000000 | O19: 5000000 | P19: 5000000 | Q19: 5000000 | R19: 5000000
B20: Income Tax Expense | C20: $ - | D20: 0 | E20: 0 | F20: 0 | G20: 0 | H20: 0 | I20: =(I18-I19)*0.25 -> 5198737.5 | J20: =(J18-J19)*0.25 -> 31146174 | K20: =(K18-K19)*0.25 -> 65515983 | L20: =(L18-L19)*0.25 -> 1.1086678e+08 | M20: =(M18-M19)*0.25 -> 1.9908737e+08 | N20: =(N18-N19)*0.25 -> 2.8595186e+08 | O20: =(O18-O19)*0.25 -> 4.4791946e+08 | P20: =(P18-P19)*0.25 -> 6.1102369e+08 | ... R20: =(R18-R19)*0.25 -> 1.2076152e+09
B22: Net Working Capital | C22: $ - | D22: 0 | E22: 0 | F22: 0 | G22: 0 | H22: 0 | I22: =I7*($C$41) -> 100000000 | J22: =J7*($C$41) -> 130000000 | K22: =K7*($C$41) -> 169000000 | L22: =L7*($C$41) -> 219700000 | M22: =M7*($C$41) -> 285610000 | N22: =N7*($C$41) -> 3.71293e+08 | O22: =O7*($C$41) -> 482680900 | P22: =P7*($C$41) -> 6.2748517e+08 | ... R22: =R7*($C$41) -> 1.0604499e+09
B23: Net Change in WC | C23: $ - | D23: 0 | E23: 0 | F23: 0 | G23: 0 | H23: 0 | I23: =I22-H22 -> 100000000 | J23: =J22-I22 -> 30000000 | K23: =K22-J22 -> 39000000 | L23: =L22-K22 -> 50700000 | M23: =M22-L22 -> 65910000 | N23: =N22-M22 -> 85683000 | O23: =O22-N22 -> 1.113879e+08 | P23: =P22-O22 -> 1.4480427e+08 | ... R23: =R22-Q22 -> 2.4471922e+08
B24: Capital Expenditure | C24: $ - | D24: =$C$42 -> 40000000 | E24: =$C$42 -> 40000000 | F24: =$C$42 -> 40000000 | G24: =$C$42 -> 40000000 | H24: =$C$42 -> 40000000 | I24: 0 | J24: 0 | K24: 0 | L24: 0 | M24: 0 | N24: 0 | O24: 0 | P24: 0 | Q24: 0 | R24: 0
B26: Free Cash Flow | C26: 0 | D26: =D18+D19-D20-D23-D24 -> -345000000 | E26: =E18+E19-E20-E23-E24 -> -353000000 | F26: =F18+F19-F20-F23-F24 -> -361400000 | G26: =G18+G19-G20-G23-G24 -> -370220000 | H26: =H18+H19-H20-H23-H24 -> -379481000 | I26: =I18+I19-I20-I23-I24 -> -74403788 | J26: =J18+J19-J20-J23-J24 -> 73438523 | K26: =K18+K19-K20-K23-K24 -> 1.6754795e+08 | ... R26: =R18+R19-R20-R23-R24 -> 3.3881263e+09
B27: Cumulative Free Cashflow | C27: 0 | D27: =D26+C27 -> -345000000 | E27: =D27+E26 -> -698000000 | F27: =E27+F26 -> -1059400000 | G27: =F27+G26 -> -1429620000 | H27: =G27+H26 -> -1809101000 | I27: =H27+I26 -> -1.8835048e+09 | J27: =I27+J26 -> -1.8100663e+09 | K27: =J27+K26 -> -1.6425183e+09 | L27: =K27+L26 -> -1.350618e+09 | ... R27: =Q27+R26 -> 8.7175274e+09
B29: Option 2: X15 Expansion
B30: Base case / bare minimum to comply with laws
B31: Value Drivers
B32: Volume in 2030 | C32: 20000 | D32: units
B33: Volume Growth rate | C33: 0.3
B34: Price per unit | C34: 100000 | I34: 2030 | J34: 2031 | K34: 2032 | L34: 2033 | M34: 2034 | N34: 2035 | O34: 2036 | P34: 2037 | Q34: 2038 | R34: 2039
B35: Cost per unit (timeline to the right) | I35: 80000 | J35: 80000 | K35: 80000 | L35: 80000 | M35: 78000 | N35: 78000 | O35: 76000 | P35: 76000 | Q35: 75000 | R35: 74000
B36: Warranty cost per unit | C36: 1000
B37: Selling and Admin in 2025 | C37: 160000000
B38: Selling and Admin growth rate | C38: 0.05
B39: Depreciation | C39: 5000000 | D39: per year
B40: Development Expense | C40: 150000000 | D40: per year
B41: Net working capital | C41: 0.05 | D41: of sales
B42: Capital Expenditure | C42: 40000000 | D42: per year
B43: Tax Rate | C43: 0.25
B44: Interest/Discount rate | C44: 0.15
B46: Net Present Value | C46: =NPV($C$44,D26:R26)+C26 -> 4.9627308e+08

Sheet Sensitve Analysis #1 Option 2
C2: 0 | D2: 1 | E2: 2 | F2: 3 | G2: 4 | H2: 5 | I2: 6 | J2: 7 | K2: 8 | L2: 9 | M2: 10 | N2: 11 | O2: 12 | P2: 13 | Q2: 14 | R2: 15
C3: 45658 | D3: 2025 | E3: 2026 | F3: 2027 | G3: 2028 | H3: 2029 | I3: 2030 | J3: 2031 | K3: 2032 | L3: 2033 | M3: 2034 | N3: 2035 | O3: 2036 | P3: 2037 | Q3: 2038 | R3: 2039
B5: Volume | C5: 0 | D5: 0 | E5: 0 | F5: 0 | G5: 0 | H5: 0 | I5: =C33 -> 10000 | J5: =I5*(1+$C$34) -> 13000 | K5: =J5*(1+$C$34) -> 16900 | L5: =K5*(1+$C$34) -> 21970 | M5: =L5*(1+$C$34) -> 28561 | N5: =M5*(1+$C$34) -> 37129.3 | O5: =N5*(1+$C$34) -> 48268.09 | P5: =O5*(1+$C$34) -> 62748.517 | Q5: =P5*(1+$C$34) -> 81573.072 | R5: =Q5*(1+$C$34) -> 106044.99
B7: Revenue | C7: 0 | D7: 0 | E7: 0 | F7: 0 | G7: 0 | H7: 0 | I7: =I5*($C$35) -> 1000000000 | J7: =J5*($C$35) -> 1300000000 | K7: =K5*($C$35) -> 1690000000 | L7: =L5*($C$35) -> 2197000000 | M7: =M5*($C$35) -> 2856100000 | N7: =N5*($C$35) -> 3.71293e+09 | O7: =O5*($C$35) -> 4826809000 | P7: =P5*($C$35) -> 6.2748517e+09 | ... R7: =R5*($C$35) -> 1.0604499e+10
B9: Std. Cost | C9: 0 | D9: 0 | E9: 0 | F9: 0 | G9: 0 | H9: 0 | I9: =I5*(I36) -> 800000000 | J9: =J5*(J36) -> 1040000000 | K9: =K5*(K36) -> 1352000000 | L9: =L5*(L36) -> 1757600000 | M9: =M5*(M36) -> 2227758000 | N9: =N5*(N36) -> 2896085400 | O9: =O5*(O36) -> 3.6683748e+09 | P9: =P5*(P36) -> 4.7688873e+09 | ... R9: =R5*(R36) -> 7.8473295e+09
B10: Warranty | C10: 0 | D10: 0 | E10: 0 | F10: 0 | G10: 0 | H10: 0 | I10: =I5*($C$37) -> 10000000 | J10: =J5*($C$37) -> 13000000 | K10: =K5*($C$37) -> 16900000 | L10: =L5*($C$37) -> 21970000 | M10: =M5*($C$37) -> 28561000 | N10: =N5*($C$37) -> 37129300 | O10: =O5*($C$37) -> 48268090 | P10: =P5*($C$37) -> 62748517 | ... R10: =R5*($C$37) -> 1.0604499e+08
B11: Total COGS | C11: 0 | D11: 0 | E11: 0 | F11: 0 | G11: 0 | H11: 0 | I11: =I9+I10 -> 810000000 | J11: =J9+J10 -> 1053000000 | K11: =K9+K10 -> 1368900000 | L11: =L9+L10 -> 1779570000 | M11: =M9+M10 -> 2256319000 | N11: =N9+N10 -> 2933214700 | O11: =O9+O10 -> 3.7166429e+09 | P11: =P9+P10 -> 4.8316358e+09 | ... R11: =R9+R10 -> 7.9533745e+09
B13: Gross Margin $ | C13: 0 | D13: 0 | E13: 0 | F13: 0 | G13: 0 | H13: 0 | I13: =I7-I11 -> 190000000 | J13: =J7-J11 -> 247000000 | K13: =K7-K11 -> 321100000 | L13: =L7-L11 -> 417430000 | M13: =M7-M11 -> 599781000 | N13: =N7-N11 -> 7.797153e+08 | O13: =O7-O11 -> 1.1101661e+09 | P13: =P7-P11 -> 1443215891 | ... R13: =R7-R11 -> 2.6511248e+09
B15: Selling and Admin O/H | C15: 0 | D15: 160000000 | E15: =D15*(1+$C$39) -> 168000000 | F15: =E15*(1+$C$39) -> 176400000 | G15: =F15*(1+$C$39) -> 185220000 | H15: =G15*(1+$C$39) -> 194481000 | I15: =H15*(1+$C$39) -> 204205050 | J15: =I15*(1+$C$39) -> 2.144153e+08 | K15: =J15*(1+$C$39) -> 2.2513607e+08 | L15: =K15*(1+$C$39) -> 2.3639287e+08 | ... R15: =Q15*(1+$C$39) -> 3.1678906e+08
B16: Development Expense | C16: 0 | D16: =$C$41 -> 150000000 | E16: =$C$41 -> 150000000 | F16: =$C$41 -> 150000000 | G16: =$C$41 -> 150000000 | H16: =$C$41 -> 150000000 | I16: =$C$41 -> 150000000 | J16: =$C$41 -> 150000000 | K16: =$C$41 -> 150000000 | ... R16: =$C$41 -> 150000000
B18: EBITDA | C18: =C13-C15-C16 -> 0 | D18: =D13-D15-D16 -> -310000000 | E18: =E13-E15-E16 -> -318000000 | F18: =F13-F15-F16 -> -326400000 | G18: =G13-G15-G16 -> -335220000 | H18: =H13-H15-H16 -> -344481000 | I18: =I13-I15-I16 -> -164205050 | J18: =J13-J15-J16 -> -1.174153e+08 | ... R18: =R13-R15-R16 -> 2.1843358e+09
B19: Depreciation | C19: 0 | D19: 5000000 | E19: 5000000 | F19: 5000000 | G19: 5000000 | H19: 5000000 | I19: 5000000 | J19: 5000000 | K19: 5000000 | L19: 5000000 | M19: 5000000 | N19: 5000000 | O19: 5000000 | P19: 5000000 | Q19: 5000000 | R19: 5000000
B20: Income Tax Expense | C20: 0 | D20: 0 | E20: 0 | F20: 0 | G20: 0 | H20: 0 | I20: =(I18-I19)*0.25 -> -42301262 | J20: =(J18-J19)*0.25 -> -30603826 | K20: =(K18-K19)*0.25 -> -14759017 | L20: =(L18-L19)*0.25 -> 6509282.2 | M20: =(M18-M19)*0.25 -> 49142121 | N20: =(N18-N19)*0.25 -> 91023040 | O20: =(O18-O19)*0.25 -> 1.7037794e+08 | P20: =(P18-P19)*0.25 -> 2.5021972e+08 | ... R20: =(R18-R19)*0.25 -> 5.4483395e+08
B22: Net Working Capital | C22: 0 | D22: 0 | E22: 0 | F22: 0 | G22: 0 | H22: 0 | I22: =I7*($C$42) -> 50000000 | J22: =J7*($C$42) -> 65000000 | K22: =K7*($C$42) -> 84500000 | L22: =L7*($C$42) -> 109850000 | M22: =M7*($C$42) -> 142805000 | N22: =N7*($C$42) -> 1.856465e+08 | O22: =O7*($C$42) -> 241340450 | P22: =P7*($C$42) -> 3.1374259e+08 | ... R22: =R7*($C$42) -> 5.3022497e+08
B23: Net Change in WC | C23: 0 | D23: 0 | E23: 0 | F23: 0 | G23: 0 | H23: 0 | I23: =I22-H22 -> 50000000 | J23: =J22-I22 -> 15000000 | K23: =K22-J22 -> 19500000 | L23: =L22-K22 -> 25350000 | M23: =M22-L22 -> 32955000 | N23: =N22-M22 -> 42841500 | O23: =O22-N22 -> 55693950 | P23: =P22-O22 -> 72402135 | ... R23: =R22-Q22 -> 1.2235961e+08
B24: Capital Expenditure | C24: 0 | D24: =$C$43 -> 40000000 | E24: =$C$43 -> 40000000 | F24: =$C$43 -> 40000000 | G24: =$C$43 -> 40000000 | H24: =$C$43 -> 40000000 | I24: 0 | J24: 0 | K24: 0 | L24: 0 | M24: 0 | N24: 0 | O24: 0 | P24: 0 | Q24: 0 | R24: 0
B26: Free Cash Flow | C26: 0 | D26: =D18+D19-D20-D23-D24 -> -345000000 | E26: =E18+E19-E20-E23-E24 -> -353000000 | F26: =F18+F19-F20-F23-F24 -> -361400000 | G26: =G18+G19-G20-G23-G24 -> -370220000 | H26: =H18+H19-H20-H23-H24 -> -379481000 | I26: =I18+I19-I20-I23-I24 -> -1.6690379e+08 | J26: =J18+J19-J20-J23-J24 -> -96811477 | K26: =K18+K19-K20-K23-K24 -> -53777051 | ... R26: =R18+R19-R20-R23-R24 -> 1.5221422e+09
B27: Cumulative Free Cashflow | C27: 0 | D27: =C27+D26 -> -345000000 | E27: =D27+E26 -> -698000000 | F27: =E27+F26 -> -1059400000 | G27: =F27+G26 -> -1429620000 | H27: =G27+H26 -> -1809101000 | I27: =H27+I26 -> -1.9760048e+09 | J27: =I27+J26 -> -2.0728163e+09 | K27: =J27+K26 -> -2.1265933e+09 | ... R27: =Q27+R26 -> 1.9597873e+09
B29: Sensitve Analysis #1: Volume for option 2 decreased by 50%
B30: Option 2: X15 Expansion
B31: Base case / bare minimum to comply with laws
B32: Value Drivers
B33: Volume in 2030 | C33: =20000*50% -> 10000 | D33: units
B34: Volume Growth rate | C34: 0.3
B35: Price per unit | C35: 100000 | I35: 2030 | J35: 2031 | K35: 2032 | L35: 2033 | M35: 2034 | N35: 2035 | O35: 2036 | P35: 2037 | Q35: 2038 | R35: 2039
B36: Cost per unit (timeline to the right) | I36: 80000 | J36: 80000 | K36: 80000 | L36: 80000 | M36: 78000 | N36: 78000 | O36: 76000 | P36: 76000 | Q36: 75000 | R36: 74000
B37: Warranty cost per unit | C37: 1000
B38: Selling and Admin in 2025 | C38: 160000000
B39: Selling and Admin growth rate | C39: 0.05
B40: Depreciation | C40: 5000000 | D40: per year
B41: Development Expense | C41: 150000000 | D41: per year
B42: Net working capital | C42: 0.05 | D42: of sales
B43: Capital Expenditure | C43: 40000000 | D43: per year
B44: Tax Rate | C44: 0.25
B45: Interest/Discount rate | C45: 0.15
B47: Net Present Value | C47: =NPV($C$45,D26:R26)+C26 -> -7.1429532e+08

Sheet Sensitve Analysis #2 Option 2
C2: 0 | D2: 1 | E2: 2 | F2: 3 | G2: 4 | H2: 5 | I2: 6 | J2: 7 | K2: 8 | L2: 9 | M2: 10 | N2: 11 | O2: 12 | P2: 13 | Q2: 14 | R2: 15
C3: 45658 | D3: 2025 | E3: 2026 | F3: 2027 | G3: 2028 | H3: 2029 | I3: 2030 | J3: 2031 | K3: 2032 | L3: 2033 | M3: 2034 | N3: 2035 | O3: 2036 | P3: 2037 | Q3: 2038 | R3: 2039
B5: Volume | C5: 0 | D5: 0 | E5: 0 | F5: 0 | G5: 0 | H5: 0 | I5: 20000 | J5: =I5*(1+$C$34) -> 26000 | K5: =J5*(1+$C$34) -> 33800 | L5: =K5*(1+$C$34) -> 43940 | M5: =L5*(1+$C$34) -> 57122 | N5: =M5*(1+$C$34) -> 74258.6 | O5: =N5*(1+$C$34) -> 96536.18 | P5: =O5*(1+$C$34) -> 125497.03 | Q5: =P5*(1+$C$34) -> 163146.14 | R5: =Q5*(1+$C$34) -> 212089.99
B7: Revenue | C7: 0 | D7: 0 | E7: 0 | F7: 0 | G7: 0 | H7: 0 | I7: =I5*($C$35) -> 2000000000 | J7: =J5*($C$35) -> 2600000000 | K7: =K5*($C$35) -> 3380000000 | L7: =L5*($C$35) -> 4394000000 | M7: =M5*($C$35) -> 5712200000 | N7: =N5*($C$35) -> 7.42586e+09 | O7: =O5*($C$35) -> 9653618000 | P7: =P5*($C$35) -> 1.2549703e+10 | ... R7: =R5*($C$35) -> 2.1208999e+10
B9: Std. Cost | C9: 0 | D9: 0 | E9: 0 | F9: 0 | G9: 0 | H9: 0 | I9: =I5*(I36) -> 1616000000 | J9: =J5*(J36) -> 2100800000 | K9: =K5*(K36) -> 2731040000 | L9: =L5*(L36) -> 3550352000 | M9: =M5*(M36) -> 4500071160 | N9: =N5*(N36) -> 5850092508 | O9: =O5*(O36) -> 7.4101172e+09 | P9: =P5*(P36) -> 9.6331523e+09 | ... R9: =R5*(R36) -> 1.5851606e+10
B10: Warranty | C10: 0 | D10: 0 | E10: 0 | F10: 0 | G10: 0 | H10: 0 | I10: =I5*($C$37) -> 20000000 | J10: =J5*($C$37) -> 26000000 | K10: =K5*($C$37) -> 33800000 | L10: =L5*($C$37) -> 43940000 | M10: =M5*($C$37) -> 57122000 | N10: =N5*($C$37) -> 74258600 | O10: =O5*($C$37) -> 96536180 | P10: =P5*($C$37) -> 1.2549703e+08 | ... R10: =R5*($C$37) -> 2.1208999e+08
B11: Total COGS | C11: 0 | D11: 0 | E11: 0 | F11: 0 | G11: 0 | H11: 0 | I11: =I9+I10 -> 1636000000 | J11: =J9+J10 -> 2126800000 | K11: =K9+K10 -> 2764840000 | L11: =L9+L10 -> 3594292000 | M11: =M9+M10 -> 4557193160 | N11: =N9+N10 -> 5924351108 | O11: =O9+O10 -> 7.5066534e+09 | P11: =P9+P10 -> 9.7586494e+09 | ... R11: =R9+R10 -> 1.6063696e+10
B13: Gross Margin $ | C13: 0 | D13: 0 | E13: 0 | F13: 0 | G13: 0 | H13: 0 | I13: =I7-I11 -> 364000000 | J13: =J7-J11 -> 473200000 | K13: =K7-K11 -> 615160000 | L13: =L7-L11 -> 799708000 | M13: =M7-M11 -> 1155006840 | N13: =N7-N11 -> 1.5015089e+09 | O13: =O7-O11 -> 2.1469646e+09 | P13: =P7-P11 -> 2.791054e+09 | ... R13: =R7-R11 -> 5.1453031e+09
B15: Selling and Admin O/H | C15: 0 | D15: 160000000 | E15: =D15*(1+$C$39) -> 168000000 | F15: =E15*(1+$C$39) -> 176400000 | G15: =F15*(1+$C$39) -> 185220000 | H15: =G15*(1+$C$39) -> 194481000 | I15: =H15*(1+$C$39) -> 204205050 | J15: =I15*(1+$C$39) -> 2.144153e+08 | K15: =J15*(1+$C$39) -> 2.2513607e+08 | L15: =K15*(1+$C$39) -> 2.3639287e+08 | ... R15: =Q15*(1+$C$39) -> 3.1678906e+08
B16: Development Expense | C16: 0 | D16: =$C$41 -> 150000000 | E16: =$C$41 -> 150000000 | F16: =$C$41 -> 150000000 | G16: =$C$41 -> 150000000 | H16: =$C$41 -> 150000000 | I16: =$C$41 -> 150000000 | J16: =$C$41 -> 150000000 | K16: =$C$41 -> 150000000 | ... R16: =$C$41 -> 150000000
B18: EBITDA | C18: =C13-C15-C16 -> 0 | D18: =D13-D15-D16 -> -310000000 | E18: =E13-E15-E16 -> -318000000 | F18: =F13-F15-F16 -> -326400000 | G18: =G13-G15-G16 -> -335220000 | H18: =H13-H15-H16 -> -344481000 | I18: =I13-I15-I16 -> 9794950 | J18: =J13-J15-J16 -> 1.087847e+08 | ... R18: =R13-R15-R16 -> 4.678514e+09
B19: Depreciation | C19: 0 | D19: 5000000 | E19: 5000000 | F19: 5000000 | G19: 5000000 | H19: 5000000 | I19: 5000000 | J19: 5000000 | K19: 5000000 | L19: 5000000 | M19: 5000000 | N19: 5000000 | O19: 5000000 | P19: 5000000 | Q19: 5000000 | R19: 5000000
B20: Income Tax Expense | C20: 0 | D20: 0 | E20: 0 | F20: 0 | G20: 0 | H20: 0 | I20: =(I18-I19)*0.25 -> 1198737.5 | J20: =(J18-J19)*0.25 -> 25946174 | K20: =(K18-K19)*0.25 -> 58755983 | L20: =(L18-L19)*0.25 -> 1.0207878e+08 | M20: =(M18-M19)*0.25 -> 1.8794858e+08 | N20: =(N18-N19)*0.25 -> 2.7147144e+08 | O20: =(O18-O19)*0.25 -> 4.2957759e+08 | P20: =(P18-P19)*0.25 -> 5.8717926e+08 | ... R20: =(R18-R19)*0.25 -> 1.1683785e+09
B22: Net Working Capital | C22: 0 | D22: 0 | E22: 0 | F22: 0 | G22: 0 | H22: 0 | I22: =I7*($C$42) -> 100000000 | J22: =J7*($C$42) -> 130000000 | K22: =K7*($C$42) -> 169000000 | L22: =L7*($C$42) -> 219700000 | M22: =M7*($C$42) -> 285610000 | N22: =N7*($C$42) -> 3.71293e+08 | O22: =O7*($C$42) -> 482680900 | P22: =P7*($C$42) -> 6.2748517e+08 | ... R22: =R7*($C$42) -> 1.0604499e+09
B23: Net Change in WC | C23: 0 | D23: 0 | E23: 0 | F23: 0 | G23: 0 | H23: 0 | I23: =I22-H22 -> 100000000 | J23: =J22-I22 -> 30000000 | K23: =K22-J22 -> 39000000 | L23: =L22-K22 -> 50700000 | M23: =M22-L22 -> 65910000 | N23: =N22-M22 -> 85683000 | O23: =O22-N22 -> 1.113879e+08 | P23: =P22-O22 -> 1.4480427e+08 | ... R23: =R22-Q22 -> 2.4471922e+08
B24: Capital Expenditure | C24: 0 | D24: =$C$43 -> 40000000 | E24: =$C$43 -> 40000000 | F24: =$C$43 -> 40000000 | G24: =$C$43 -> 40000000 | H24: =$C$43 -> 40000000 | I24: 0 | J24: 0 | K24: 0 | L24: 0 | M24: 0 | N24: 0 | O24: 0 | P24: 0 | Q24: 0 | R24: 0
B26: Free Cash Flow | C26: 0 | D26: =D18+D19-D20-D23-D24 -> -345000000 | E26: =E18+E19-E20-E23-E24 -> -353000000 | F26: =F18+F19-F20-F23-F24 -> -361400000 | G26: =G18+G19-G20-G23-G24 -> -370220000 | H26: =H18+H19-H20-H23-H24 -> -379481000 | I26: =I18+I19-I20-I23-I24 -> -86403788 | J26: =J18+J19-J20-J23-J24 -> 57838523 | K26: =K18+K19-K20-K23-K24 -> 1.4726795e+08 | ... R26: =R18+R19-R20-R23-R24 -> 3.2704163e+09
B27: Cumulative Free Cashflow | C27: 0 | D27: =C27+D26 -> -345000000 | E27: =D27+E26 -> -698000000 | F27: =E27+F26 -> -1059400000 | G27: =F27+G26 -> -1429620000 | H27: =G27+H26 -> -1809101000 | I27: =H27+I26 -> -1.8955048e+09 | J27: =I27+J26 -> -1.8376663e+09 | K27: =J27+K26 -> -1.6903983e+09 | ... R27: =Q27+R26 -> 8.2303872e+09
B29: Sensitve Analysis #2: cost/unit increase by 1%
B30: Option 2: X15 Expansion
B31: Base case / bare minimum to comply with laws
B32: Value Drivers
B33: Volume in 2030 | C33: 20000 | D33: units
B34: Volume Growth rate | C34: 0.3
B35: Price per unit | C35: 100000 | I35: 2030 | J35: 2031 | K35: 2032 | L35: 2033 | M35: 2034 | N35: 2035 | O35: 2036 | P35: 2037 | Q35: 2038 | R35: 2039
B36: Cost per unit (timeline to the right) | I36: ='Option 2'!I35*1.01 -> 80800 | J36: ='Option 2'!J35*1.01 -> 80800 | K36: ='Option 2'!K35*1.01 -> 80800 | L36: ='Option 2'!L35*1.01 -> 80800 | M36: ='Option 2'!M35*1.01 -> 78780 | N36: ='Option 2'!N35*1.01 -> 78780 | O36: ='Option 2'!O35*1.01 -> 76760 | P36: ='Option 2'!P35*1.01 -> 76760 | ... R36: ='Option 2'!R35*1.01 -> 74740
B37: Warranty cost per unit | C37: 1000
B38: Selling and Admin in 2025 | C38: 160000000
B39: Selling and Admin growth rate | C39: 0.05
B40: Depreciation | C40: 5000000 | D40: per year
B41: Development Expense | C41: 150000000 | D41: per year
B42: Net working capital | C42: 0.05 | D42: of sales
B43: Capital Expenditure | C43: 40000000 | D43: per year
B44: Tax Rate | C44: 0.25
B45: Interest/Discount rate | C45: 0.15
B47: Net Present Value | C47: =NPV($C$45,D26:R26)+C26 -> 4.0415281e+08

Sheet Option 3
C2: 0 | D2: 1 | E2: 2 | F2: 3 | G2: 4 | H2: 5 | I2: 6 | J2: 7 | K2: 8 | L2: 9 | M2: 10 | N2: 11 | O2: 12 | P2: 13 | Q2: 14 | R2: 15
C3: 45658 | D3: 2025 | E3: 2026 | F3: 2027 | G3: 2028 | H3: 2029 | I3: 2030 | J3: 2031 | K3: 2032 | L3: 2033 | M3: 2034 | N3: 2035 | O3: 2036 | P3: 2037 | Q3: 2038 | R3: 2039
B5: Volume | C5: 0 | D5: 0 | E5: 0 | F5: 0 | G5: 0 | H5: 0 | I5: =C32 -> 20000 | J5: =I5*(1+$C$33) -> 24000 | K5: =J5*(1+$C$33) -> 28800 | L5: =K5*(1+$C$33) -> 34560 | M5: =L5*(1+$C$33) -> 41472 | N5: =M5*(1+$C$33) -> 49766.4 | O5: =N5*(1+$C$33) -> 59719.68 | P5: =O5*(1+$C$33) -> 71663.616 | Q5: =P5*(1+$C$33) -> 85996.339 | R5: =Q5*(1+$C$33) -> 103195.61
B7: Revenue | C7: 0 | D7: 0 | E7: 0 | F7: 0 | G7: 0 | H7: 0 | I7: =I5*($C$34) -> 3000000000 | J7: =J5*($C$34) -> 3600000000 | K7: =K5*($C$34) -> 4320000000 | L7: =L5*($C$34) -> 5184000000 | M7: =M5*($C$34) -> 6220800000 | N7: =N5*($C$34) -> 7464960000 | O7: =O5*($C$34) -> 8957952000 | P7: =P5*($C$34) -> 10749542400 | ... R7: =R5*($C$34) -> 1.5479341e+10
B9: Std. Cost | C9: 0 | D9: 0 | E9: 0 | F9: 0 | G9: 0 | H9: 0 | I9: =I5*(I35) -> 1600000000 | J9: =J5*(J35) -> 1920000000 | K9: =K5*(K35) -> 2304000000 | L9: =L5*(L35) -> 2764800000 | M9: =M5*(M35) -> 3234816000 | N9: =N5*(N35) -> 3881779200 | O9: =O5*(O35) -> 4538695680 | P9: =P5*(P35) -> 5446434816 | ... R9: =R5*(R35) -> 7.6364749e+09
B10: Warranty | C10: 0 | D10: 0 | E10: 0 | F10: 0 | G10: 0 | H10: 0 | I10: =I5*($C$36) -> 20000000 | J10: =J5*($C$36) -> 24000000 | K10: =K5*($C$36) -> 28800000 | L10: =L5*($C$36) -> 34560000 | M10: =M5*($C$36) -> 41472000 | N10: =N5*($C$36) -> 49766400 | O10: =O5*($C$36) -> 59719680 | P10: =P5*($C$36) -> 71663616 | ... R10: =R5*($C$36) -> 1.0319561e+08
B11: Total COGS | C11: 0 | D11: 0 | E11: 0 | F11: 0 | G11: 0 | H11: 0 | I11: =I9+I10 -> 1620000000 | J11: =J9+J10 -> 1944000000 | K11: =K9+K10 -> 2332800000 | L11: =L9+L10 -> 2799360000 | M11: =M9+M10 -> 3276288000 | N11: =N9+N10 -> 3931545600 | O11: =O9+O10 -> 4598415360 | P11: =P9+P10 -> 5518098432 | ... R11: =R9+R10 -> 7.7396705e+09
B13: Gross Margin $ | C13: 0 | D13: 0 | E13: 0 | F13: 0 | G13: 0 | H13: 0 | I13: =I7-I11 -> 1380000000 | J13: =J7-J11 -> 1656000000 | K13: =K7-K11 -> 1987200000 | L13: =L7-L11 -> 2384640000 | M13: =M7-M11 -> 2944512000 | N13: =N7-N11 -> 3533414400 | O13: =O7-O11 -> 4359536640 | P13: =P7-P11 -> 5231443968 | ... R13: =R7-R11 -> 7.7396705e+09
B15: Selling and Admin O/H | C15: 0 | D15: 160000000 | E15: =D15*(1+$C$38) -> 168000000 | F15: =E15*(1+$C$38) -> 176400000 | G15: =F15*(1+$C$38) -> 185220000 | H15: =G15*(1+$C$38) -> 194481000 | I15: =H15*(1+$C$38) -> 204205050 | J15: =I15*(1+$C$38) -> 2.144153e+08 | K15: =J15*(1+$C$38) -> 2.2513607e+08 | L15: =K15*(1+$C$38) -> 2.3639287e+08 | ... R15: =Q15*(1+$C$38) -> 3.1678906e+08
B16: Development Expense | C16: 0 | D16: =$C$40 -> 200000000 | E16: =$C$40 -> 200000000 | F16: =$C$40 -> 200000000 | G16: =$C$40 -> 200000000 | H16: =$C$40 -> 200000000 | I16: =$C$40 -> 200000000 | J16: =$C$40 -> 200000000 | K16: =$C$40 -> 200000000 | ... R16: =$C$40 -> 200000000
B18: EBITDA | C18: 0 | D18: =D13-D15-D16 -> -360000000 | E18: =E13-E15-E16 -> -368000000 | F18: =F13-F15-F16 -> -376400000 | G18: =G13-G15-G16 -> -385220000 | H18: =H13-H15-H16 -> -394481000 | I18: =I13-I15-I16 -> 975794950 | J18: =J13-J15-J16 -> 1.2415847e+09 | K18: =K13-K15-K16 -> 1.5620639e+09 | ... R18: =R13-R15-R16 -> 7.2228815e+09
B19: Depreciation | C19: 0 | D19: 5000000 | E19: 5000000 | F19: 5000000 | G19: 5000000 | H19: 5000000 | I19: 5000000 | J19: 5000000 | K19: 5000000 | L19: 5000000 | M19: 5000000 | N19: 5000000 | O19: 5000000 | P19: 5000000 | Q19: 5000000 | R19: 5000000
B20: Income Tax Expense | C20: 0 | D20: 0 | E20: 0 | F20: 0 | G20: 0 | H20: 0 | I20: =(I18-I19)*0.25 -> 2.4269874e+08 | J20: =(J18-J19)*0.25 -> 3.0914617e+08 | K20: =(K18-K19)*0.25 -> 3.8926598e+08 | L20: =(L18-L19)*0.25 -> 4.8581178e+08 | M20: =(M18-M19)*0.25 -> 6.2282487e+08 | N20: =(N18-N19)*0.25 -> 7.6694781e+08 | O20: =(O18-O19)*0.25 -> 9.7022059e+08 | P20: =(P18-P19)*0.25 -> 1.1847767e+09 | ... R20: =(R18-R19)*0.25 -> 1.8044704e+09
B22: Net Working Capital | C22: 0 | D22: 0 | E22: 0 | F22: 0 | G22: 0 | H22: 0 | I22: =I7*($C$41) -> 150000000 | J22: =J7*($C$41) -> 180000000 | K22: =K7*($C$41) -> 216000000 | L22: =L7*($C$41) -> 259200000 | M22: =M7*($C$41) -> 311040000 | N22: =N7*($C$41) -> 373248000 | O22: =O7*($C$41) -> 447897600 | P22: =P7*($C$41) -> 537477120 | ... R22: =R7*($C$41) -> 7.7396705e+08
B23: Net Change in WC | C23: 0 | D23: 0 | E23: 0 | F23: 0 | G23: 0 | H23: 0 | I23: =I22-H22 -> 150000000 | J23: =J22-I22 -> 30000000 | K23: =K22-J22 -> 36000000 | L23: =L22-K22 -> 43200000 | M23: =M22-L22 -> 51840000 | N23: =N22-M22 -> 62208000 | O23: =O22-N22 -> 74649600 | P23: =P22-O22 -> 89579520 | ... R23: =R22-Q22 -> 1.2899451e+08
B24: Capital Expenditure | C24: 0 | D24: =$C$42 -> 100000000 | E24: =$C$42 -> 100000000 | F24: =$C$42 -> 100000000 | G24: =$C$42 -> 100000000 | H24: =$C$42 -> 100000000 | I24: 0 | J24: 0 | K24: 0 | L24: 0 | M24: 0 | N24: 0 | O24: 0 | P24: 0 | Q24: 0 | R24: 0
B26: Free Cash Flow | C26: 0 | D26: =D18+D19-D20-D23-D24 -> -455000000 | E26: =E18+E19-E20-E23-E24 -> -463000000 | F26: =F18+F19-F20-F23-F24 -> -471400000 | G26: =G18+G19-G20-G23-G24 -> -480220000 | H26: =H18+H19-H20-H23-H24 -> -489481000 | I26: =I18+I19-I20-I23-I24 -> 5.8809621e+08 | J26: =J18+J19-J20-J23-J24 -> 9.0743852e+08 | K26: =K18+K19-K20-K23-K24 -> 1.1417979e+09 | ... R26: =R18+R19-R20-R23-R24 -> 5.2944166e+09
B27: Cumulative Free Cashflow | C27: 0 | D27: =D26+C27 -> -455000000 | E27: =D27+E26 -> -918000000 | F27: =E27+F26 -> -1389400000 | G27: =F27+G26 -> -1869620000 | H27: =G27+H26 -> -2359101000 | I27: =H27+I26 -> -1.7710048e+09 | J27: =I27+J26 -> -8.6356626e+08 | K27: =J27+K26 -> 2.7823168e+08 | L27: =K27+L26 -> 1.702467e+09 | ... R27: =Q27+R26 -> 2.168819e+10
B29: Option 3: X15H Hydrogen Engine
B30: Base case / bare minimum to comply with laws
B31: Value Drivers
B32: Volume in 2030 | C32: 20000 | D32: units
B33: Volume Growth rate | C33: 0.2
B34: Price per unit | C34: 150000 | I34: 2030 | J34: 2031 | K34: 2032 | L34: 2033 | M34: 2034 | N34: 2035 | O34: 2036 | P34: 2037 | Q34: 2038 | R34: 2039
B35: Cost per unit (timeline to the right) | I35: 80000 | J35: 80000 | K35: 80000 | L35: 80000 | M35: 78000 | N35: 78000 | O35: 76000 | P35: 76000 | Q35: 75000 | R35: 74000
B36: Warranty cost per unit | C36: 1000
B37: Selling and Admin in 2025 | C37: 160000000
B38: Selling and Admin growth rate | C38: 0.05
B39: Depreciation | C39: 5000000 | D39: per year
B40: Development Expense | C40: 200000000 | D40: per year
B41: Net working capital | C41: 0.05 | D41: of sales
B42: Capital Expenditure | C42: 100000000 | D42: per year
B43: Tax Rate | C43: 0.25
B44: Interest/Discount rate | C44: 0.15
B46: Net Present Value | C46: =NPV($C$44,D26:R26)+C26 -> 3.0891057e+09

Sheet Sensitve Analysis #1 Option 3
C2: 0 | D2: 1 | E2: 2 | F2: 3 | G2: 4 | H2: 5 | I2: 6 | J2: 7 | K2: 8 | L2: 9 | M2: 10 | N2: 11 | O2: 12 | P2: 13 | Q2: 14 | R2: 15
C3: 45658 | D3: 2025 | E3: 2026 | F3: 2027 | G3: 2028 | H3: 2029 | I3: 2030 | J3: 2031 | K3: 2032 | L3: 2033 | M3: 2034 | N3: 2035 | O3: 2036 | P3: 2037 | Q3: 2038 | R3: 2039
B5: Volume | C5: 0 | D5: 0 | E5: 0 | F5: 0 | G5: 0 | H5: 0 | I5: =C33 -> 10000 | J5: =I5*(1+$C$34) -> 12000 | K5: =J5*(1+$C$34) -> 14400 | L5: =K5*(1+$C$34) -> 17280 | M5: =L5*(1+$C$34) -> 20736 | N5: =M5*(1+$C$34) -> 24883.2 | O5: =N5*(1+$C$34) -> 29859.84 | P5: =O5*(1+$C$34) -> 35831.808 | Q5: =P5*(1+$C$34) -> 42998.17 | R5: =Q5*(1+$C$34) -> 51597.804
B7: Revenue | C7: 0 | D7: 0 | E7: 0 | F7: 0 | G7: 0 | H7: 0 | I7: =I5*($C$35) -> 1500000000 | J7: =J5*($C$35) -> 1800000000 | K7: =K5*($C$35) -> 2160000000 | L7: =L5*($C$35) -> 2592000000 | M7: =M5*($C$35) -> 3110400000 | N7: =N5*($C$35) -> 3732480000 | O7: =O5*($C$35) -> 4478976000 | P7: =P5*($C$35) -> 5374771200 | ... R7: =R5*($C$35) -> 7.7396705e+09
B9: Std. Cost | C9: 0 | D9: 0 | E9: 0 | F9: 0 | G9: 0 | H9: 0 | I9: =I5*(I36) -> 800000000 | J9: =J5*(J36) -> 960000000 | K9: =K5*(K36) -> 1152000000 | L9: =L5*(L36) -> 1382400000 | M9: =M5*(M36) -> 1617408000 | N9: =N5*(N36) -> 1940889600 | O9: =O5*(O36) -> 2269347840 | P9: =P5*(P36) -> 2723217408 | ... R9: =R5*(R36) -> 3.8182375e+09
B10: Warranty | C10: 0 | D10: 0 | E10: 0 | F10: 0 | G10: 0 | H10: 0 | I10: =I5*$C$37 -> 10000000 | J10: =J5*$C$37 -> 12000000 | K10: =K5*$C$37 -> 14400000 | L10: =L5*$C$37 -> 17280000 | M10: =M5*$C$37 -> 20736000 | N10: =N5*$C$37 -> 24883200 | O10: =O5*$C$37 -> 29859840 | P10: =P5*$C$37 -> 35831808 | ... R10: =R5*$C$37 -> 51597804
B11: Total COGS | C11: 0 | D11: 0 | E11: 0 | F11: 0 | G11: 0 | H11: 0 | I11: =I9+I10 -> 810000000 | J11: =J9+J10 -> 972000000 | K11: =K9+K10 -> 1166400000 | L11: =L9+L10 -> 1399680000 | M11: =M9+M10 -> 1638144000 | N11: =N9+N10 -> 1965772800 | O11: =O9+O10 -> 2299207680 | P11: =P9+P10 -> 2759049216 | ... R11: =R9+R10 -> 3.8698353e+09
B13: Gross Margin $ | C13: 0 | D13: 0 | E13: 0 | F13: 0 | G13: 0 | H13: 0 | I13: =I7-I11 -> 690000000 | J13: =J7-J11 -> 828000000 | K13: =K7-K11 -> 993600000 | L13: =L7-L11 -> 1192320000 | M13: =M7-M11 -> 1472256000 | N13: =N7-N11 -> 1766707200 | O13: =O7-O11 -> 2179768320 | P13: =P7-P11 -> 2615721984 | ... R13: =R7-R11 -> 3.8698353e+09
B15: Selling and Admin O/H | C15: 0 | D15: 160000000 | E15: =D15*(1+$C$39) -> 168000000 | F15: =E15*(1+$C$39) -> 176400000 | G15: =F15*(1+$C$39) -> 185220000 | H15: =G15*(1+$C$39) -> 194481000 | I15: =H15*(1+$C$39) -> 204205050 | J15: =I15*(1+$C$39) -> 2.144153e+08 | K15: =J15*(1+$C$39) -> 2.2513607e+08 | L15: =K15*(1+$C$39) -> 2.3639287e+08 | ... R15: =Q15*(1+$C$39) -> 3.1678906e+08
B16: Development Expense | C16: 0 | D16: =$C$41 -> 200000000 | E16: =$C$41 -> 200000000 | F16: =$C$41 -> 200000000 | G16: =$C$41 -> 200000000 | H16: =$C$41 -> 200000000 | I16: =$C$41 -> 200000000 | J16: =$C$41 -> 200000000 | K16: =$C$41 -> 200000000 | ... R16: =$C$41 -> 200000000
B18: EBITDA | C18: =C13-C15-C16 -> 0 | D18: =D13-D15-D16 -> -360000000 | E18: =E13-E15-E16 -> -368000000 | F18: =F13-F15-F16 -> -376400000 | G18: =G13-G15-G16 -> -385220000 | H18: =H13-H15-H16 -> -394481000 | I18: =I13-I15-I16 -> 285794950 | J18: =J13-J15-J16 -> 4.135847e+08 | ... R18: =R13-R15-R16 -> 3.3530462e+09
B19: Depreciation | C19: 0 | D19: 5000000 | E19: 5000000 | F19: 5000000 | G19: 5000000 | H19: 5000000 | I19: 5000000 | J19: 5000000 | K19: 5000000 | L19: 5000000 | M19: 5000000 | N19: 5000000 | O19: 5000000 | P19: 5000000 | Q19: 5000000 | R19: 5000000
B20: Income Tax Expense | C20: 0 | D20: 0 | E20: 0 | F20: 0 | G20: 0 | H20: 0 | I20: =(I18-I19)*0.25 -> 70198738 | J20: =(J18-J19)*0.25 -> 1.0214617e+08 | K20: =(K18-K19)*0.25 -> 1.4086598e+08 | L20: =(L18-L19)*0.25 -> 1.8773178e+08 | M20: =(M18-M19)*0.25 -> 2.5476087e+08 | N20: =(N18-N19)*0.25 -> 3.2527101e+08 | O20: =(O18-O19)*0.25 -> 4.2527851e+08 | P20: =(P18-P19)*0.25 -> 5.3084624e+08 | ... R20: =(R18-R19)*0.25 -> 8.3701155e+08
B22: Net Working Capital | C22: 0 | D22: 0 | E22: 0 | F22: 0 | G22: 0 | H22: 0 | I22: =I7*($C$42) -> 75000000 | J22: =J7*($C$42) -> 90000000 | K22: =K7*($C$42) -> 108000000 | L22: =L7*($C$42) -> 129600000 | M22: =M7*($C$42) -> 155520000 | N22: =N7*($C$42) -> 186624000 | O22: =O7*($C$42) -> 223948800 | P22: =P7*($C$42) -> 268738560 | ... R22: =R7*($C$42) -> 3.8698353e+08
B23: Net Change in WC | C23: 0 | D23: 0 | E23: 0 | F23: 0 | G23: 0 | H23: 0 | I23: =I22-H22 -> 75000000 | J23: =J22-I22 -> 15000000 | K23: =K22-J22 -> 18000000 | L23: =L22-K22 -> 21600000 | M23: =M22-L22 -> 25920000 | N23: =N22-M22 -> 31104000 | O23: =O22-N22 -> 37324800 | P23: =P22-O22 -> 44789760 | ... R23: =R22-Q22 -> 64497254
B24: Capital Expenditure | C24: 0 | D24: =$C$43 -> 100000000 | E24: =$C$43 -> 100000000 | F24: =$C$43 -> 100000000 | G24: =$C$43 -> 100000000 | H24: =$C$43 -> 100000000 | I24: 0 | J24: 0 | K24: 0 | L24: 0 | M24: 0 | N24: 0 | O24: 0 | P24: 0 | Q24: 0 | R24: 0
B26: Free Cash Flow | C26: 0 | D26: =D18+D19-D20-D23-D24 -> -455000000 | E26: =E18+E19-E20-E23-E24 -> -463000000 | F26: =F18+F19-F20-F23-F24 -> -471400000 | G26: =G18+G19-G20-G23-G24 -> -480220000 | H26: =H18+H19-H20-H23-H24 -> -489481000 | I26: =I18+I19-I20-I23-I24 -> 1.4559621e+08 | J26: =J18+J19-J20-J23-J24 -> 3.0143852e+08 | K26: =K18+K19-K20-K23-K24 -> 4.1459795e+08 | ... R26: =R18+R19-R20-R23-R24 -> 2.4565374e+09
B27: Cumulative Free Cashflow | C27: 0 | D27: =C27+D26 -> -455000000 | E27: =D27+E26 -> -918000000 | F27: =E27+F26 -> -1389400000 | G27: =F27+G26 -> -1869620000 | H27: =G27+H26 -> -2359101000 | I27: =H27+I26 -> -2.2135048e+09 | J27: =I27+J26 -> -1.9120663e+09 | K27: =J27+K26 -> -1.4974683e+09 | ... R27: =Q27+R26 -> 7.9826186e+09
B29: Sensitve Analysis #1: Volume for option 3 decreased by 50%
B30: Option 3: X15H Hydrogen Engine
B31: Base case / bare minimum to comply with laws
B32: Value Drivers
B33: Volume in 2030 | C33: =20000*50% -> 10000 | D33: units
B34: Volume Growth rate | C34: 0.2
B35: Price per unit | C35: 150000 | I35: 2030 | J35: 2031 | K35: 2032 | L35: 2033 | M35: 2034 | N35: 2035 | O35: 2036 | P35: 2037 | Q35: 2038 | R35: 2039
B36: Cost per unit (timeline to the right) | I36: 80000 | J36: 80000 | K36: 80000 | L36: 80000 | M36: 78000 | N36: 78000 | O36: 76000 | P36: 76000 | Q36: 75000 | R36: 74000
B37: Warranty cost per unit | C37: 1000
B38: Selling and Admin in 2025 | C38: 160000000
B39: Selling and Admin growth rate | C39: 0.05
B40: Depreciation | C40: 5000000 | D40: per year
B41: Development Expense | C41: 200000000 | D41: per year
B42: Net working capital | C42: 0.05 | D42: of sales
B43: Capital Expenditure | C43: 100000000 | D43: per year
B44: Tax Rate | C44: 0.25
B45: Interest/Discount rate | C45: 0.15
B47: Net Present Value | C47: =NPV($C$45,D26:R26)+C26 -> 3.5096716e+08

Sheet Sensitve Analysis #2 Option 3
C2: 0 | D2: 1 | E2: 2 | F2: 3 | G2: 4 | H2: 5 | I2: 6 | J2: 7 | K2: 8 | L2: 9 | M2: 10 | N2: 11 | O2: 12 | P2: 13 | Q2: 14 | R2: 15
C3: 45658 | D3: 2025 | E3: 2026 | F3: 2027 | G3: 2028 | H3: 2029 | I3: 2030 | J3: 2031 | K3: 2032 | L3: 2033 | M3: 2034 | N3: 2035 | O3: 2036 | P3: 2037 | Q3: 2038 | R3: 2039
B5: Volume | C5: 0 | D5: 0 | E5: 0 | F5: 0 | G5: 0 | H5: 0 | I5: =C33 -> 20000 | J5: =I5*(1+$C$34) -> 24000 | K5: =J5*(1+$C$34) -> 28800 | L5: =K5*(1+$C$34) -> 34560 | M5: =L5*(1+$C$34) -> 41472 | N5: =M5*(1+$C$34) -> 49766.4 | O5: =N5*(1+$C$34) -> 59719.68 | P5: =O5*(1+$C$34) -> 71663.616 | Q5: =P5*(1+$C$34) -> 85996.339 | R5: =Q5*(1+$C$34) -> 103195.61
B7: Revenue | C7: 0 | D7: 0 | E7: 0 | F7: 0 | G7: 0 | H7: 0 | I7: =I5*($C$35) -> 3000000000 | J7: =J5*($C$35) -> 3600000000 | K7: =K5*($C$35) -> 4320000000 | L7: =L5*($C$35) -> 5184000000 | M7: =M5*($C$35) -> 6220800000 | N7: =N5*($C$35) -> 7464960000 | O7: =O5*($C$35) -> 8957952000 | P7: =P5*($C$35) -> 10749542400 | ... R7: =R5*($C$35) -> 1.5479341e+10
B9: Std. Cost | C9: 0 | D9: 0 | E9: 0 | F9: 0 | G9: 0 | H9: 0 | I9: =I5*(I36) -> 1616000000 | J9: =J5*(J36) -> 1939200000 | K9: =K5*(K36) -> 2327040000 | L9: =L5*(L36) -> 2792448000 | M9: =M5*(M36) -> 3267164160 | N9: =N5*(N36) -> 3920596992 | O9: =O5*(O36) -> 4.5840826e+09 | P9: =P5*(P36) -> 5.5008992e+09 | ... R9: =R5*(R36) -> 7.7128397e+09
B10: Warranty | C10: 0 | D10: 0 | E10: 0 | F10: 0 | G10: 0 | H10: 0 | I10: =I5*$C$37 -> 20000000 | J10: =J5*$C$37 -> 24000000 | K10: =K5*$C$37 -> 28800000 | L10: =L5*$C$37 -> 34560000 | M10: =M5*$C$37 -> 41472000 | N10: =N5*$C$37 -> 49766400 | O10: =O5*$C$37 -> 59719680 | P10: =P5*$C$37 -> 71663616 | ... R10: =R5*$C$37 -> 1.0319561e+08
B11: Total COGS | C11: 0 | D11: 0 | E11: 0 | F11: 0 | G11: 0 | H11: 0 | I11: =I9+I10 -> 1636000000 | J11: =J9+J10 -> 1963200000 | K11: =K9+K10 -> 2355840000 | L11: =L9+L10 -> 2827008000 | M11: =M9+M10 -> 3308636160 | N11: =N9+N10 -> 3970363392 | O11: =O9+O10 -> 4.6438023e+09 | P11: =P9+P10 -> 5.5725628e+09 | ... R11: =R9+R10 -> 7.8160353e+09
B13: Gross Margin $ | C13: 0 | D13: 0 | E13: 0 | F13: 0 | G13: 0 | H13: 0 | I13: =I7-I11 -> 1364000000 | J13: =J7-J11 -> 1636800000 | K13: =K7-K11 -> 1964160000 | L13: =L7-L11 -> 2356992000 | M13: =M7-M11 -> 2912163840 | N13: =N7-N11 -> 3494596608 | O13: =O7-O11 -> 4.3141497e+09 | P13: =P7-P11 -> 5.1769796e+09 | ... R13: =R7-R11 -> 7.6633058e+09
B15: Selling and Admin O/H | C15: 0 | D15: 160000000 | E15: =D15*(1+$C$39) -> 168000000 | F15: =E15*(1+$C$39) -> 176400000 | G15: =F15*(1+$C$39) -> 185220000 | H15: =G15*(1+$C$39) -> 194481000 | I15: =H15*(1+$C$39) -> 204205050 | J15: =I15*(1+$C$39) -> 2.144153e+08 | K15: =J15*(1+$C$39) -> 2.2513607e+08 | L15: =K15*(1+$C$39) -> 2.3639287e+08 | ... R15: =Q15*(1+$C$39) -> 3.1678906e+08
B16: Development Expense | C16: 0 | D16: =$C$41 -> 200000000 | E16: =$C$41 -> 200000000 | F16: =$C$41 -> 200000000 | G16: =$C$41 -> 200000000 | H16: =$C$41 -> 200000000 | I16: =$C$41 -> 200000000 | J16: =$C$41 -> 200000000 | K16: =$C$41 -> 200000000 | ... R16: =$C$41 -> 200000000
B18: EBITDA | C18: =C13-C15-C16 -> 0 | D18: =D13-D15-D16 -> -360000000 | E18: =E13-E15-E16 -> -368000000 | F18: =F13-F15-F16 -> -376400000 | G18: =G13-G15-G16 -> -385220000 | H18: =H13-H15-H16 -> -394481000 | I18: =I13-I15-I16 -> 959794950 | J18: =J13-J15-J16 -> 1.2223847e+09 | ... R18: =R13-R15-R16 -> 7.1465167e+09
B19: Depreciation | C19: 0 | D19: 5000000 | E19: 5000000 | F19: 5000000 | G19: 5000000 | H19: 5000000 | I19: 5000000 | J19: 5000000 | K19: 5000000 | L19: 5000000 | M19: 5000000 | N19: 5000000 | O19: 5000000 | P19: 5000000 | Q19: 5000000 | R19: 5000000
B20: Income Tax Expense | C20: 0 | D20: 0 | E20: 0 | F20: 0 | G20: 0 | H20: 0 | I20: =(I18-I19)*0.25 -> 2.3869874e+08 | J20: =(J18-J19)*0.25 -> 3.0434617e+08 | K20: =(K18-K19)*0.25 -> 3.8350598e+08 | L20: =(L18-L19)*0.25 -> 4.7889978e+08 | M20: =(M18-M19)*0.25 -> 6.1473783e+08 | N20: =(N18-N19)*0.25 -> 7.5724337e+08 | O20: =(O18-O19)*0.25 -> 9.5887385e+08 | P20: =(P18-P19)*0.25 -> 1.1711607e+09 | ... R20: =(R18-R19)*0.25 -> 1.7853792e+09
B22: Net Working Capital | C22: 0 | D22: 0 | E22: 0 | F22: 0 | G22: 0 | H22: 0 | I22: =I7*($C$42) -> 150000000 | J22: =J7*($C$42) -> 180000000 | K22: =K7*($C$42) -> 216000000 | L22: =L7*($C$42) -> 259200000 | M22: =M7*($C$42) -> 311040000 | N22: =N7*($C$42) -> 373248000 | O22: =O7*($C$42) -> 447897600 | P22: =P7*($C$42) -> 537477120 | ... R22: =R7*($C$42) -> 7.7396705e+08
B23: Net Change in WC | C23: 0 | D23: 0 | E23: 0 | F23: 0 | G23: 0 | H23: 0 | I23: =I22-H22 -> 150000000 | J23: =J22-I22 -> 30000000 | K23: =K22-J22 -> 36000000 | L23: =L22-K22 -> 43200000 | M23: =M22-L22 -> 51840000 | N23: =N22-M22 -> 62208000 | O23: =O22-N22 -> 74649600 | P23: =P22-O22 -> 89579520 | ... R23: =R22-Q22 -> 1.2899451e+08
